Workbook

Sheet Summary
B2: AMZN 1.0 | F2: AMZN 2.0 | J2: HEB Repurchase | N2: Uses of Net Cash to Partnership | R2: Summary
B4: Amazon Sale 1.0 | F4: Amazon Sale 2.0 | J4: HEB Repurchase | N4: Amazon Sale 2.0 | R4: Prosperity Loan
B5: Estimated Sale Date | D5: 46289 | F5: Estimated Sale Date | H5: =H82 -> 46351 | J5: Estimated Repurchase Date | L5: 46387 | N5: Sources | R5: Current Loan Balance | T5: =D31 -> 11613112
J6: Sources | N6: Net Cash to Partnership - Amazon 1.0 | P6: =D25 -> 2246641.7 | R6: Amazon 1.0 Paydown | T6: =-D18 -> -2714144.4
B7: Amazon Sales Proceeds (PSA) - 53 Acres | D7: 33336904 | F7: Amazon Sales Proceeds (PSA) - 25.22 Acres | H7: =13.5*25.22*43560 -> 14830873 | J7: Prosperity Loan | K7: 0.65 | L7: =SUM(L12:L13)*K7 -> 7358335.7 | N7: Net Cash to Partnership - Amazon 2.0 | P7: =H25 -> 5521789.2 | R7: Amazon 1.0 Loan Draw to Refi RI | T7: =D50 -> 3000000
B8: Soft Cost Reim | D8: 276080 | F8: Soft Cost Reim | J8: Equity | L8: =L15-L7 -> 5962180.8 | N8: Total Sources | P8: =SUM(P6:P7) -> 7768431 | R8: Amazon 2.0 Paydown | T8: =-H18 -> -3585586.9
B9: Less: KBC Broker Fee (3%) | D9: =-SUM(D7:D7)*3% -> -1000107.1 | F9: Less: KBC Broker Fee (3%) | H9: =-H7*3% -> -444926.2 | J9: Total Sources | L9: =SUM(L7:L8) -> 13320517 | R9: Amazon 2.0 Loan Draw for Infrastructure | T9: =H36 -> 7500000
B10: Less: Title | D10: =-150000*1.5 -> -225000 | F10: Less: Title | H10: =-150000*1.5 -> -225000 | N10: Uses | R10: HEB Site Repurchase | T10: =L7 -> 7358335.7
B11: Less: Legal | D11: -200000 | F11: Less: Legal | H11: -200000 | J11: Uses | N11: Preferred Unit Payments | P11: =4850000+1850000 -> 6700000 | R11: HEB Site LOC | T11: =L22 -> 2200000
B12: Less: Misc. Closing Costs | D12: -350000 | F12: Less: Misc. Closing Costs | H12: -200000 | J12: Repurchase Price | L12: ='HEB Repurchase Price'!G114 -> 11098546 | N12: Operating Reserves | P12: =P8-SUM(P11:P11) -> 1068431 | R12: Total Prosperity Loan Amount | T12: =SUM(T5:T11) -> 25371717
J13: Closing Costs | K13: 0.02 | L13: =L12*K13 -> 221970.91 | N13: Total Uses | P13: =SUM(P11:P12) -> 7768431
B14: Gross Sale Proceeds | D14: =SUM(D7:D13) -> 31837876 | F14: Gross Sale Proceeds | H14: =SUM(H7:H13) -> 13760947 | J14: Interest & Operating Reserve | L14: 2000000 | R14: Total Land Acres | T14: =L30 -> 201.26224
J15: Total Uses | L15: =SUM(L12:L14) -> 13320517 | R15: Loan Basis $/SF | T15: =T12/T14/43560 -> 2.8940077
B16: Uses of Gross Sale Proceeds | F16: Uses of Gross Sale Proceeds | R16: Land Market Value (Amazon 1.0) | T16: 14.5
B17: Infrastructure Escrow - 1.0 | D17: ='AMZL 1.0 Infrastructure'!C7 -> 7032241.3 | F17: Infrastructure Escrow - 2.0 | H17: =H35 -> 4653570.9 | J17: HEB Repurchase Prosperity Loan Amount | L17: =L7 -> 7358335.7 | R17: LTV | T17: =T15/T16 -> 0.19958674
B18: Prosperity Loan Paydown | D18: =D45 -> 2714144.4 | F18: Prosperity Loan Paydown | H18: =IFERROR(H72, 0) -> 3585586.9 | J18: Prosperity Revolving LOC
B19: Texas Partners Bank | D19: 9000000 | J19: Master Planning | L19: 500000
B20: Cadence Bank | D20: 5730000 | J20: Architect | L20: 700000
B21: Real International | D21: 3100000 | J21: Engineering | L21: 1000000
B22: Accrual - Real International | D22: 2014849.1 | F22: Total Uses | H22: =SUM(H17:H21) -> 8239157.8 | J22: Total Revolving LOC | L22: =SUM(L19:L21) -> 2200000
B23: Total Uses | D23: =SUM(D17:D22) -> 29591235
J24: Total Loan Amount | L24: =SUM(L17,L22) -> 9558335.7
B25: Net Cash to Partnership | D25: =D14-D23 -> 2246641.7 | F25: Net Cash to Partnership | H25: =H14-H22 -> 5521789.2
B27: Prosperity Loan Release | F27: Loan Status after Amazon Sale 2.0 | J27: Loan Status
B28: (a) 250% Loan Par | G28: Before | H28: After | K28: Before | L28: After
B29: Original Loan Proceeds | D29: 12700000 | F29: Loan Balance | G29: =D59 -> 11898968 | H29: =G29-H18 -> 8313380.8 | J29: Loan Balance | K29: =H52 -> 15813381 | L29: =K29+L24 -> 25371717
B30: Loan Paydown to Date | D30: -1086887.9 | F30: Collateral | G30: =D60 -> 209.2349 | H30: =G30-H68 -> 184.0149 | J30: Collateral | K30: =H53 -> 184.0149 | L30: =K30+'HEB Repurchase Price'!G115/43560 -> 201.26224
B31: Outstanding Loan Amount | D31: =SUM(D29:D30) -> 11613112 | F31: Loan $/SF | G31: =G29/G30/43560 -> 1.3055313 | H31: =H29/H30/43560 -> 1.0371386 | J31: Loan $/SF | K31: =K29/K30/43560 -> 1.9728037 | L31: =L29/L30/43560 -> 2.8940077
B33: Total Collateral Size (Acres) | D33: 208.3279 | F33: Infrastructure Funding
B34: - Released Land Size (Acres) | D34: -10.5 | F34: Sources
B35: Adjusted Collateral Size (Acres) | D35: =SUM(D33:D34) -> 197.8279 | F35: Funding from Land Partnership | H35: =H40-H36 -> 4653570.9
F36: Funding from Prosperity LOC | H36: 7500000
B37: 250% Loan Par on Released Land | C37: 2.5 | D37: =ABS(D31/D33*D34*C37) -> 1463290.3 | F37: Total Sources | H37: =SUM(H35:H36) -> 12153571
B39: (b) 55% of Net Sale Proceeds | F39: Uses
B40: Total Net Sale Proceeds | D40: =D14-D17 -> 24805635 | F40: Infrastructure Costs | H40: ='AMZL 2.0 Infrasructure'!C9 -> 12153571
B41: Total Land for Sale (Acres) | D41: 52.78 | F41: Total Uses | H41: =SUM(H40) -> 12153571
B42: Released Land Size (Acres) | D42: 10.5
B43: 55% of Net Sale Proceeds on Released Land | C43: 0.55 | D43: =D40/D41*D42*C43 -> 2714144.4 | F43: Loan Draw Schedule
G44: Dates | H44: $ Amount
B45: Loan Amount Release - greater of (a) and (b) | D45: =MAX(D37,D43) -> 2714144.4 | F45: Draw #1 | G45: 46539 | H45: 3000000
...

Sheet Loan Payoff Sensitivity
B2: Fully Drawn Loan Balance | C2: =Summary!L29 -> 25371717
B3: Collateral Acreage | C3: =Summary!L30 -> 201.26224
B4: Loan Basis ($/Land SF) | C4: =Summary!L31 -> 2.8940077
B6: Scenario 1
B7: 250% Loan Par Release ($/SF) | C7: =C4*250% -> 7.2350193
B8: Acres Required to Pay Off Loan | C8: =C2/C7/43560 -> 80.504895
B9: Payoff Acres as % of Collateral | C9: =C8/$C$3 -> 0.4
B11: Scenario 2
B12: Amazon Industrial Land Comp ($/SF) | C12: 14.5
B13: Acres Required to Pay Off Loan | C13: =C2/C12/43560 -> 40.169274
B14: Payoff Acres as % of Collateral | C14: =C13/$C$3 -> 0.19958674

Sheet AMZL 1.0 Infrastructure
B1: DUA4 Budget Summary
B2: Project | C2: Seller Allocation | D2: Seller % | E2: Purchaser Allocation | F2: Purchaser % | G2: Total
B3: Spirit Dr. | C3: 1904299.2 | D3: 0.5 | E3: 1904299.2 | F3: 0.5 | G3: 3808598.3
B4: Foundry Ave. | C4: 1766409.8 | D4: 0.5 | E4: 1766409.8 | F4: 0.5 | G4: 3532819.5
B5: Channel D | C5: =G5*D5 -> 3314722.4 | D5: 1 | E5: =G5*F5 -> 0 | F5: 0 | G5: 3314722.4
B6: Sitewide | C6: 46809.956 | D6: 0.078057411 | E6: 552876.29 | F6: 0.92194259 | G6: 599686.24
B7: Total | C7: =SUM(C3:C6) -> 7032241.3 | D7: 0.68137896 | E7: =SUM(E3:E6) -> 4223585.2 | F7: 0.31862104 | G7: =SUM(G3:G6) -> 11255827

Sheet AMZL 2.0 Infrasructure
B1: SUS1 Budget Summary
B2: Project | C2: Seller Allocation | D2: Seller % | E2: Purchaser Allocation | F2: Purchaser % | G2: Total
B3: Spirit Dr. (Foundry to ph. 1 plat) | C3: =$G3*D3 -> 2079086.9 | D3: 0.5 | E3: =$G3*F3 -> 2079086.9 | F3: 0.5 | G3: 4158173.8
B4: Spirit Dr. Ext. | C4: =$G4*D4 -> 1092559.3 | D4: 0.5 | E4: =$G4*F4 -> 1092559.3 | F4: 0.5 | G4: 2185118.5
B5: Foundry Phase 2 | C5: =$G5*D5 -> 1484248.3 | D5: 0.5 | E5: =$G5*F5 -> 1484248.3 | F5: 0.5 | G5: 2968496.7
B6: Velocity Crossing & Spirit Dr. Ext. | C6: =$G6*D6 -> 4107274.8 | D6: 0.5 | E6: =$G6*F6 -> 4107274.8 | F6: 0.5 | G6: 8214549.6
B7: WW 84" | C7: =$G7*D7 -> 3354188.3 | D7: 1 | E7: =$G7*F7 -> 0 | F7: 0 | G7: 3354188.3
B8: Sitewide | C8: =$G8*D8 -> 36213.224 | D8: 0.14916399 | E8: =$G8*F8 -> 206561.35 | F8: 0.85083601 | G8: 242774.58
B9: Total | C9: =SUM(C3:C8) -> 12153571 | D9: =C9/G9 -> 0.57536322 | E9: =SUM(E3:E8) -> 8969730.7 | F9: =E9/G9 -> 0.42463678 | G9: =SUM(G3:G8) -> 21123302

Sheet HEB Repurchase Price
A1: Closing Date | B1: =Summary!L5 -> 46387
A3: Type | B3: Amount | C3: Date | D3: Closing Date | E3: Days | F3: Year Fraction | G3: Repurchase Value
A4: Legal | B4: 2169.07 | C4: 42327 | D4: =B1 -> 46387 | E4: =_xlfn.DAYS(D4,C4) -> 4060 | F4: =E4/365 -> 11.123288 | G4: =B4*(1.075^F4) -> 4848.8523
A5: Engineering | B5: 8500 | C5: 42360 | D5: =D4 -> 46387 | E5: =_xlfn.DAYS(D5,C5) -> 4027 | F5: =E5/365 -> 11.032877 | G5: =B5*(1.075^F5) -> 18877.507
A6: Legal | B6: 1405.57 | C6: 42383 | D6: =D5 -> 46387 | E6: =_xlfn.DAYS(D6,C6) -> 4004 | F6: =E6/365 -> 10.969863 | G6: =B6*(1.075^F6) -> 3107.4134
A7: Legal | B7: 419.7 | C7: 42415 | D7: =D6 -> 46387 | E7: =_xlfn.DAYS(D7,C7) -> 3972 | F7: =E7/365 -> 10.882192 | G7: =B7*(1.075^F7) -> 922.00208
A8: Legal | B8: 4133.3 | C8: 42443 | D8: =D7 -> 46387 | E8: =_xlfn.DAYS(D8,C8) -> 3944 | F8: =E8/365 -> 10.805479 | G8: =B8*(1.075^F8) -> 9029.8481
A9: Legal | B9: 5186.1 | C9: 42488 | D9: =D8 -> 46387 | E9: =_xlfn.DAYS(D9,C9) -> 3899 | F9: =E9/365 -> 10.682192 | G9: =B9*(1.075^F9) -> 11229.286
A10: Legal | B10: 1105.2 | C10: 42523 | D10: =D9 -> 46387 | E10: =_xlfn.DAYS(D10,C10) -> 3864 | F10: =E10/365 -> 10.586301 | G10: =B10*(1.075^F10) -> 2376.5138
A11: Legal | B11: 551.7 | C11: 42534 | D11: =D10 -> 46387 | E11: =_xlfn.DAYS(D11,C11) -> 3853 | F11: =E11/365 -> 10.556164 | G11: =B11*(1.075^F11) -> 1183.7388
A12: Environmental | B12: 2400 | C12: 42551 | D12: =D11 -> 46387 | E12: =_xlfn.DAYS(D12,C12) -> 3836 | F12: =E12/365 -> 10.509589 | G12: =B12*(1.075^F12) -> 5132.1731
A13: Legal | B13: 861.3 | C13: 42565 | D13: =D12 -> 46387 | E13: =_xlfn.DAYS(D13,C13) -> 3822 | F13: =E13/365 -> 10.471233 | G13: =B13*(1.075^F13) -> 1836.7066
A14: Engineering | B14: 1514.3 | C14: 42586 | D14: =D13 -> 46387 | E14: =_xlfn.DAYS(D14,C14) -> 3801 | F14: =E14/365 -> 10.413699 | G14: =B14*(1.075^F14) -> 3215.8087
A15: Legal | B15: 1251.35 | C15: 42611 | D15: =D14 -> 46387 | E15: =_xlfn.DAYS(D15,C15) -> 3776 | F15: =E15/365 -> 10.345205 | G15: =B15*(1.075^F15) -> 2644.2701
A16: Legal | B16: 2823.95 | C16: 42632 | D16: =D15 -> 46387 | E16: =_xlfn.DAYS(D16,C16) -> 3755 | F16: =E16/365 -> 10.287671 | G16: =B16*(1.075^F16) -> 5942.6063
... A22: Purchase Price - 1.663 acres | B22: 778174.56 | C22: 42720 | D22: =D21 -> 46387 | E22: =_xlfn.DAYS(D22,C22) -> 3667 | F22: =E22/365 -> 10.046575 | G22: =B22*(1.075^F22) -> 1609253.8
A23: Engineering | B23: 2000 | C23: 42726 | D23: =D21 -> 46387 | E23: =_xlfn.DAYS(D23,C23) -> 3661 | F23: =E23/365 -> 10.030137 | G23: =B23*(1.075^F23) -> 4131.0571
A24: Legal | B24: 11944.97 | C24: 42747 | D24: =D23 -> 46387 | E24: =_xlfn.DAYS(D24,C24) -> 3640 | F24: =E24/365 -> 9.9726027 | G24: =B24*(1.075^F24) -> 24570.229
A25: Engineering | B25: 17018.76 | C25: 42824 | D25: =D24 -> 46387 | E25: =_xlfn.DAYS(D25,C25) -> 3563 | F25: =E25/365 -> 9.7616438 | G25: =B25*(1.075^F25) -> 34476.737
A26: Legal | B26: 1816.5 | C26: 42900 | D26: =D25 -> 46387 | E26: =_xlfn.DAYS(D26,C26) -> 3487 | F26: =E26/365 -> 9.5534247 | G26: =B26*(1.075^F26) -> 3624.8814
A27: SDA Draw | B27: 4377.22 | C27: 43004 | D27: =D26 -> 46387 | E27: =_xlfn.DAYS(D27,C27) -> 3383 | F27: =E27/365 -> 9.2684932 | G27: =B27*(1.075^F27) -> 8556.7237
A28: Legal | B28: 1422.1 | C28: 43034 | D28: =D27 -> 46387 | E28: =_xlfn.DAYS(D28,C28) -> 3353 | F28: =E28/365 -> 9.1863014 | G28: =B28*(1.075^F28) -> 2763.4891
A29: SDA Draw | B29: 5665.47 | C29: 43034 | D29: =D28 -> 46387 | E29: =_xlfn.DAYS(D29,C29) -> 3353 | F29: =E29/365 -> 9.1863014 | G29: =B29*(1.075^F29) -> 11009.398
A30: SDA Draw | B30: 18066.63 | C30: 43067 | D30: =D29 -> 46387 | E30: =_xlfn.DAYS(D30,C30) -> 3320 | F30: =E30/365 -> 9.0958904 | G30: =B30*(1.075^F30) -> 34879.086
A31: SDA Draw | B31: 19693.32 | C31: 43105 | D31: =D30 -> 46387 | E31: =_xlfn.DAYS(D31,C31) -> 3282 | F31: =E31/365 -> 8.9917808 | G31: =B31*(1.075^F31) -> 37734.358
A32: Property Tax | B32: 42123.87 | C32: 43131 | D32: =D31 -> 46387 | E32: =_xlfn.DAYS(D32,C32) -> 3256 | F32: =E32/365 -> 8.9205479 | G32: =B32*(1.075^F32) -> 80298.785
A33: Property Tax | B33: 2143.24 | C33: 43131 | D33: =D32 -> 46387 | E33: =_xlfn.DAYS(D33,C33) -> 3256 | F33: =E33/365 -> 8.9205479 | G33: =B33*(1.075^F33) -> 4085.5593
A34: Property Tax | B34: 3208.46 | C34: 43131 | D34: =D33 -> 46387 | E34: =_xlfn.DAYS(D34,C34) -> 3256 | F34: =E34/365 -> 8.9205479 | G34: =B34*(1.075^F34) -> 6116.1389
A35: SDA Draw | B35: 18914.55 | C35: 43140 | D35: =D34 -> 46387 | E35: =_xlfn.DAYS(D35,C35) -> 3247 | F35: =E35/365 -> 8.8958904 | G35: =B35*(1.075^F35) -> 35991.692
... A112: Property Tax | B112: 4460.22 | C112: 46055 | D112: =D111 -> 46387 | E112: =_xlfn.DAYS(D112,C112) -> 332 | F112: =E112/365 -> 0.90958904 | G112: =B112*(1.075^F112) -> 4763.488
C114: Repurchase Price | G114: =SUM(G4:G112) -> 11098546
C115: Land Area | G115: =678874+43247+29173 -> 751294
C116: Price/SF | G116: =(G114/G115) -> 14.772573
